Workbook
Name Bajo: 1
Name SegmentaciónDeDatos_Actividades: #N/A
Name SegmentaciónDeDatos_AÑO: #N/A
Name SegmentaciónDeDatos_Consecuencia: #N/A
Name SegmentaciónDeDatos_Eficacia: #N/A
Name SegmentaciónDeDatos_Nivel_cualitativo_de_riesgo: #N/A
Name SegmentaciónDeDatos_Nivel_del_riesgo: #N/A
Name SegmentaciónDeDatos_Subclasificación: #N/A
Name SegmentaciónDeDatos_Tipo_de_peligro: #N/A

Sheet HOME
C1: MATRIZ IDENTIFICACIÓN DE PELIGROS, EVALUACIÓN Y VALORACIÓN DE RIESGOS | F1: MATRIZ IDENTIFICACIÓN DE PELIGROS, EVALUACIÓN Y VALORACIÓN DE RIESGOS

Sheet RAM
C1: Matriz Evaluacion del Riesgo RAM | H1: CODIGO COL-HSEQ-FT-006 EMISIÓN 13-07-2015 VIGENCIA 21-10-2015 VERSIÓN 2 PÁGINA 1 de 1
C5: CONSECUENCIA DEL EVENTO | G5: PROBABILIDAD
B6: Nivel | C6: Personas | D6: Medio Ambiente | E6: Activos & Financiera | F6: Reputación Empresarial | G6: 1. Remoto Una vez durante la vida de las instalaciones, menor a 1 cada 20 años | H6: 2. Improbable Una vez cada 5 a 20 años. | I6: 3. Probable Una ocurrencia entre 1 y 5 años. | J6: 4. Frecuente Una o más ocurrencias por año.
B7: 1. Menor | C7: • Lesión menor • Enfermedad menor. • Primeros auxilios requeridos. • No evacuaciones. • Amenaza implícita del propietario del terreno/activista. | D7: • Daño ambiental menor y efectos confinados al arrendamiento. • Impacto confinado al arrendamiento. | E7: • Pérdida de producción insignificante. • Pérdida de producción y equipos menor de US$50,000 • Delito menor contra la propiedad. | F7: • Inquietudes localizadas, queja única del interesado y sin atención de los medios. • Sin impacto en la reputación de Parex. • Impacto mínimo en el público. | G7: 1 | H7: 2 | I7: 3 | J7: 4
B8: 2. Moderado | C8: • Lesión con auxilio médico. • Trabajo restringido. • Evacuación del sitio de trabajo. • Amenaza específica del propietario del terreno/activista. | D8: • Daño ambiental moderado. • Impactos localizados fuera del arrendamiento o fuera del sitio. • Limpieza inmediata. | E8: • Cierre de facilidades / equipos a corto plazo ( menos de una semana) • Pérdida de producción y equipos mayor de US$50,000 hasta US$500,000 • Delito mayor contra la propiedad. | F8: • Atención breve a medios locales, quejas múltiples de los interesados. • Impacto local a corto plazo sobre la reputación de Parex. • Acción legal y/o regulatoria resultante en respuesta administrativa. | G8: 2 | H8: 4 | I8: 6 | J8: 8
B9: 3. Serio | C9: • Lesión con pérdida de tiempo. • Lesiones múltiples. • Impacto sobre la salud a corto plazo (incl. daño emocional) • Evacuación de las instalaciones y del área más cercana. • Acción violenta del dueño del terreno / activista. | D9: • Daño ambiental severo reversible o a corto plazo. • Efectos dentro del campo/bloque de operaciones. • Impactos generalizados al terreno, al agua o al aire. | E9: • Instalaciones de una semana/cierre de equipos. • Pérdida de producción y equipos mayor de US$500,000 y menor de US$10 millones. • Pérdida sustancial por robo/vandalismo. | F9: • Atención prolongada del área local, de la comunidad o noticias provinciales. • Impacto adverso sobre la reputación de Parex a nivel provincial, caída a corto plazo en el precio de la acción de Parex • Acción legal y/o regulatoria resultante en multas o acciones punitivas. | G9: 3 | H9: 6 | I9: 9 | J9: 12
B10: 4. Crítico | C10: • Fatalidad •Impacto sobre la salud a largo plazo (incl.daño emocional) •Incapacidad permanente • Evacuación de las instalaciones y de la comunidad •Acción del propietario del terreno/activista involucrando armas.. | D10: • Daño ambiental severo irreversible o a largo-plazo. • Impactos generalizados al medio ambiente sensible y/o cuerpos de agua principales / vías fluviales o aire | E10: • Instalaciones de un mes/cierre de equipos • Pérdida de producción y equipos superior a US$10 millones • Ataque/atentado terrorista | F10: • Inquietudes generalizadas con extenso cubrimiento adverso de medios nacionales o internacionales. • Impacto importante a largo plazo sobre la reputación, mercado de las acciones y precio de las acciones. • Acción resultante en procesamiento judicial y/o regulatorio, o en la suspensión de las operaciones. | G10: 4 | H10: 8 | I10: 12 | J10: 16
A12: Paso 2 - Probabilidad estimada.
B13: Nivel | C13: Descripción. | E13: Probabilidad.
B14: 4 Frecuente | C14: Se espera que el evento ocurra en este proyecto. | E14: Una o más ocurrencias por año.
B15: 3 Probable | C15: Se espera que el evento ocurra en un proyecto de Parex en los próximos 1 a 5 años, pero no necesariamente en este proyecto | E15: Una ocurrencia entre 1 y 5 años.
B16: 2 Improbable. | C16: Evento de no probable ocurrerncia basado en actuales prácticas, pero que Parex puede experimentar a nivel de Compañía, en una de las instalaciones de Parex sobre la vida promedio de las instalaciones. | E16: Una vez cada 5 a 20 años.
B17: 1 Remoto | C17: Evento de no probable ocurrencia y que no se espera que Parex experimente dicho evento, pero la industria lo ha experimentado en el pasado. | E17: Una vez durante la vida de las instalaciones, menor a 1 cada 20 años
A19: Paso 3 - Determinar el Potencial del Riesgo.
A20: Consecuencia | B20: 4 Crítico | C20: 4 | D20: 8 | E20: 12 | F20: 16
B21: 3 Serio | C21: 3 | D21: 6 | E21: 9 | F21: 12
B22: 2 Moderado | C22: 2 | D22: 4 | E22: 6 | F22: 8
B23: 1 Menor | C23: 1 | D23: 2 | E23: 3 | F23: 4
C24: 1 Remoto | D24: 2 No probable | E24: 3 Probable | F24: 4 Frecuente
B25: Probabilidad
B27: EXTREMO | C27: Extremo – Actividades STOP. No se puede proceder con el trabajo hasta que el riesgo se reduzca a su más bajo nivel. (Se requiere la aprobación del Vice Presidente y/o COO)
B28: ALTO | C28: Se deben implementar medidas de control/mitigación del riesgo Altas-Extensivas. Se deben emprender esfuerzos para reducir el riesgo a un nivel MEDIO o BAJO. (Se requiere la aprobación del Gerente del Departamento).
B29: MEDIO | C29: Se deben implementar medidas de control/mitigación de los riesgos de nivel medio, para permitir que el trabajo prosiga. Se deben emprender esfuerzos para reducir el riesgo a un nivel BAJO. (Para valoración 4 se requiere la aprobación del Supervisor de Sitio, Company Man, interventor de facilidades, obras civiles, etc. Para valoración con nivel 6 se requiere la aprobación del Líder de Operación, Coordinadores, Superintendente.)
B30: BAJO | C30: Bajo– Algunas medidas de control/mitigación del riesgo pueden ser justificadas. Representa un nivel aceptable del riesgo. ( Se requiere la aprobación del Supervisor del Sitio, Company Man).

Sheet Parametros
A1: Biológico | B1: Físico | C1: Químico | D1: Psicosocial | E1: Biomecánicas | F1: Condiciones_de_seguridad | G1: Fenómenos_naturales | I1: Nivel del riesgo | J1: Tipo de peligro
A2: 1.1 Virus | B2: 2.1 Ruido | C2: 3.1 Polvos orgánicos e inorgánicos | D2: 4.1 Gestión organizacional | E2: 5.1 Postura | F2: 6.1 Mecánico | G2: 7.1 Sismo | I2: 1 | J2: 1. Biológico
A3: 1.2 Bacterias | B3: 2.2 Iluminación | C3: 3.2 Fibras | D3: 4.2 Características de la organización del trabajo | E3: 5.2 Esfuerzos | F3: 6.2 Eléctrico | G3: 7.2 Terremoto | I3: 2 | J3: 2. Físico
A4: 1.3 Hongos | B4: 2.3 Vibración | C4: 3.3 Líquidos, nieblas | D4: 4.3 Condiciones de la tarea | E4: 5.3 Movimientos repetitivos | F4: 6.3 Locativos | G4: 7.3 Vendaval | I4: 3 | J4: 3. Químico
A5: 1.4 Ricketslas | B5: 2.4 Temperaturas extremas | C5: 3.4 Líquidos, rocíos | D5: 4.4 Características del grupo social de trabajo | E5: 5.4 Manipulación manual de cargas | F5: 6.4 Tecnológico | G5: 7.4 Inundación | I5: 4 | J5: 4. Psicosocial
A6: 1.5 Parásitos | B6: 2.5 Presión | C6: 3.5 Gases y vapores | D6: 4.5 Interface persona | F6: 6.5 Accidentes de transito | G6: 7.5 Derrumbe | I6: 6 | J6: 5. Biomecánicas
A7: 1.6 Picaduras | B7: 2.6 Radiaciones ionizantes | C7: 3.6 Humos metálicos y NO metálicos | D7: 4.6 Jornada de trabajo | F7: 6.6 Públicos | G7: 7.6 Precipitaciones | I7: 8 | J7: 6. Condiciones de seguridad
A8: 1.7 Mordeduras | B8: 2.7 Radiaciones No ionizantes | C8: 3.7 Material particulado | D8: 4.7. Carga de Trabajo | F8: 6.7 Trabajo en alturas | I8: 9 | J8: 7. Fenómenos naturales
A9: 1.8 Fluidos o excrementos | D9: 4.8 Victimización y acoso (bullying) e intimidación | F9: 6.8 Espacios confinados | I9: 12
D10: 4.9 Liderazgo y la cultura de la organización | I10: 16 | J10: Consecuencias
J11: AT
J12: EL
J13: AT/EL
B14: https://static.vecteezy.com/system/resources/previews/029/920/044/non_2x/risk-icon-on-speedometer-high-risk-meter-stock-illustration-vector.jpg | J14: Bienes y Finanzas
B15: https://img.freepik.com/vector-premium/medidor-velocimetro-vectorial-flecha-salpicadero-indicadores-verdes-amarillos-naranjas-rojos-indicador-tacometro-niveles-riesgo-miedo-bitcoin-medio-alto-criptomoneda-indice-codicia_81863-5351.jpg | J15: Reputación de la empresa
B16: https://static.vecteezy.com/system/resources/previews/002/556/994/non_2x/high-risk-concept-on-speedometer-illustration-speedometer-icon-colorful-infographic-gauge-element-vector.jpg
J17: Cargos
J18: Asistente Administrativo(a) RSE Campo
A19: Calsificación | B19: Imagen | D19: Calsificación | E19: Imagen | J19: Contratistas
A20: Biológico | B20: #VALUE! | D20: Extremo | E20: #VALUE! | J20: Coordinador(a) Administrativo(a)
A21: Físico | B21: #VALUE! | D21: Alto | E21: #VALUE! | J21: Coordinador(a) de Seguridad Campo
A22: Químico | B22: #VALUE! | D22: Medio | E22: #VALUE! | J22: Gestor de RSE
A23: Psicosocial | B23: #VALUE! | D23: Bajo | E23: #VALUE! | J23: HSEQ
A24: Biomecánicas | B24: #VALUE! | J24: Ingeniero(a) de Obras Civiles
A25: Condiciones_de_seguridad | B25: #VALUE! | J25: Ingeniero(a) de Producción
A26: Fenómenos_naturales | B26: #VALUE! | J26: Ingeniero(a) Química
J27: Ingeniero(a) Senior de Perforación
J28: Profesional TIC Campo
J29: Supervisor de Bodega
J30: Supervisor de Construcción
J31: Supervisor de Mantenimiento en Campo
J32: Supervisor de Producción
J33: Supervisor de Producción General
J34: Supervisor General de Mantenimiento
J35: Todo el personal de la locación
J36: Comunidad
J37: Visitantes
J39: Estación
... J49: Boranda

Sheet L. DE MATRICES
C2: #VALUE! | D2: LISTADO DE ACTIVIDADES DEL BLOQUE
C8: ITEM | D8: Centro de trabajo | E8: Actividades | F8: Hipervinculo | G8: Celda | H8: MATRICES ACTIVIDADES
C9: 1 | D9: EXPLORACIÓN | E9: =IF(H9="","",H9) -> Transporte terrestre | F9: =IF(C9="","",HYPERLINK("#'2026'!"&G9,"Ir a la actividad"&H9)) -> Ir a la actividadTransporte terrestre | G9: {=ADDRESS(MATCH($H9,'año26'!F:F,0),COLUMN('año26'!F:F))} -> $F$11 | H9: {=_xlfn.UNIQUE(año26[Tárea])} -> Transporte terrestre
C10: =IF(H11="",IF(H10="","",C9+1),IF(H10="","",C9+1)) -> 2 | D10: EXPLORACIÓN | E10: =IF(H10="","",H10) -> Transporte Aéreo | F10: =IF(C10="","",HYPERLINK("#'2026'!"&G10,"Ir a la actividad"&H10)) -> Ir a la actividadTransporte Aéreo | G10: {=ADDRESS(MATCH($H10,'año26'!F:F,0),COLUMN('año26'!F:F))} -> $F$27 | H10: Transporte Aéreo
C11: =IF(H12="",IF(H11="","",C10+1),IF(H11="","",C10+1)) -> 3 | D11: EXPLORACIÓN | E11: =IF(H11="","",H11) -> Transporte Fluvial | F11: =IF(C11="","",HYPERLINK("#'2026'!"&G11,"Ir a la actividad"&H11)) -> Ir a la actividadTransporte Fluvial | G11: {=ADDRESS(MATCH($H11,'año26'!F:F,0),COLUMN('año26'!F:F))} -> $F$33 | H11: Transporte Fluvial
C12: =IF(H13="",IF(H12="","",C11+1),IF(H12="","",C11+1)) -> 4 | D12: EXPLORACIÓN | E12: =IF(H12="","",H12) -> Toma de muestras | F12: =IF(C12="","",HYPERLINK("#'2026'!"&G12,"Ir a la actividad"&H12)) -> Ir a la actividadToma de muestras | G12: {=ADDRESS(MATCH($H12,'año26'!F:F,0),COLUMN('año26'!F:F))} -> $F$44 | H12: Toma de muestras
C13: =IF(H14="",IF(H13="","",C12+1),IF(H13="","",C12+1)) -> 5 | D13: EXPLORACIÓN | E13: =IF(H13="","",H13) -> Estudios geológicos | F13: =IF(C13="","",HYPERLINK("#'2026'!"&G13,"Ir a la actividad"&H13)) -> Ir a la actividadEstudios geológicos | G13: {=ADDRESS(MATCH($H13,'año26'!F:F,0),COLUMN('año26'!F:F))} -> $F$65 | H13: Estudios geológicos
C14: =IF(H15="",IF(H14="","",C13+1),IF(H14="","",C13+1)) -> 6 | D14: EXPLORACIÓN | E14: =IF(H14="","",H14) -> WELL SITE - Geología de operaciones en pozo | F14: =IF(C14="","",HYPERLINK("#'2026'!"&G14,"Ir a la actividad"&H14)) -> Ir a la actividadWELL SITE - Geología de operaciones en pozo | G14: {=ADDRESS(MATCH($H14,'año26'!F:F,0),COLUMN('año26'!F:F))} -> $F$80 | H14: WELL SITE - Geología de operaciones en pozo
C15: =IF(H16="",IF(H15="","",C14+1),IF(H15="","",C14+1)) -> 7 | D15: EXPLORACIÓN | E15: =IF(H15="","",H15) -> Well Logging - Ensamblar y conectar equipos, herramientas y registros al vástago del taladro o cables para conducir las pruebas y ensayos requeridos. Medir y calibrar tuberías y herramientas | F15: =IF(C15="","",HYPERLINK("#'2026'!"&G15,"Ir a la actividad"&H15)) -> Ir a la actividadWell Logging - Ensamblar y conectar equipos, herramientas y registros al vástago del taladro o cables para conducir las pruebas y ensayos requeridos. Medir y calibrar tuberías y herramientas | G15: {=ADDRESS(MATCH($H15,'año26'!F:F,0),COLUMN('año26'!F:F))} -> $F$93 | H15: Well Logging - Ensamblar y conectar equipos, herramientas y registros al vástago del taladro o cables para conducir las pruebas y ensayos requeridos. Medir y calibrar tuberías y herramientas
C16: =IF(H17="",IF(H16="","",C15+1),IF(H16="","",C15+1)) -> 8 | D16: EXPLORACIÓN | E16: =IF(H16="","",H16) -> Mud Logging - Monitoreo de parámetros | F16: =IF(C16="","",HYPERLINK("#'2026'!"&G16,"Ir a la actividad"&H16)) -> Ir a la actividadMud Logging - Monitoreo de parámetros | G16: {=ADDRESS(MATCH($H16,'año26'!F:F,0),COLUMN('año26'!F:F))} -> $F$102 | H16: Mud Logging - Monitoreo de parámetros
C17: =IF(H18="",IF(H17="","",C16+1),IF(H17="","",C16+1)) -> 9 | D17: EXPLORACIÓN | E17: =IF(H17="","",H17) -> REGISTROS - ACTIVIDADES ADMINISTRATIVAS - Revisión y análisis de Informes | F17: =IF(C17="","",HYPERLINK("#'2026'!"&G17,"Ir a la actividad"&H17)) -> Ir a la actividadREGISTROS - ACTIVIDADES ADMINISTRATIVAS - Revisión y análisis de Informes | G17: {=ADDRESS(MATCH($H17,'año26'!F:F,0),COLUMN('año26'!F:F))} -> $F$124 | H17: REGISTROS - ACTIVIDADES ADMINISTRATIVAS - Revisión y análisis de Informes
C18: =IF(H19="",IF(H18="","",C17+1),IF(H18="","",C17+1)) -> 10 | D18: EXPLORACIÓN | E18: =IF(H18="","",H18) -> Todas las tareas del proceso productivo | F18: =IF(C18="","",HYPERLINK("#'2026'!"&G18,"Ir a la actividad"&H18)) -> Ir a la actividadTodas las tareas del proceso productivo | G18: {=ADDRESS(MATCH($H18,'año26'!F:F,0),COLUMN('año26'!F:F))} -> $F$136 | H18: Todas las tareas del proceso productivo
C19: =IF(H20="",IF(H19="","",C18+1),IF(H19="","",C18+1)) | D19: EXPLORACIÓN | E19: =IF(H19="","",H19) | F19: =IF(C19="","",HYPERLINK("#'2026'!"&G19,"Ir a la actividad"&H19)) | G19: {=ADDRESS(MATCH($H19,'año26'!F:F,0),COLUMN('año26'!F:F))} -> #N/A
C20: =IF(H21="",IF(H20="","",C19+1),IF(H20="","",C19+1)) | D20: EXPLORACIÓN | E20: =IF(H20="","",H20) | F20: =IF(C20="","",HYPERLINK("#'2026'!"&G20,"Ir a la actividad"&H20)) | G20: {=ADDRESS(MATCH($H20,'año26'!F:F,0),COLUMN('año26'!F:F))} -> #N/A
C21: =IF(H22="",IF(H21="","",C20+1),IF(H21="","",C20+1)) | D21: EXPLORACIÓN | E21: =IF(H21="","",H21) | F21: =IF(C21="","",HYPERLINK("#'2026'!"&G21,"Ir a la actividad"&H21)) | G21: {=ADDRESS(MATCH($H21,'año26'!F:F,0),COLUMN('año26'!F:F))} -> #N/A
C22: =IF(H23="",IF(H22="","",C21+1),IF(H22="","",C21+1)) | D22: EXPLORACIÓN | E22: =IF(H22="","",H22) | F22: =IF(C22="","",HYPERLINK("#'2026'!"&G22,"Ir a la actividad"&H22)) | G22: {=ADDRESS(MATCH($H22,'año26'!F:F,0),COLUMN('año26'!F:F))} -> #N/A
C23: =IF(H24="",IF(H23="","",C22+1),IF(H23="","",C22+1)) | D23: EXPLORACIÓN | E23: =IF(H23="","",H23) | F23: =IF(C23="","",HYPERLINK("#'2026'!"&G23,"Ir a la actividad"&H23)) | G23: {=ADDRESS(MATCH($H23,'año26'!F:F,0),COLUMN('año26'!F:F))} -> #N/A
C24: =IF(H25="",IF(H24="","",C23+1),IF(H24="","",C23+1)) | D24: EXPLORACIÓN | E24: =IF(H24="","",H24) | F24: =IF(C24="","",HYPERLINK("#'2026'!"&G24,"Ir a la actividad"&H24)) | G24: {=ADDRESS(MATCH($H24,'año26'!F:F,0),COLUMN('año26'!F:F))} -> #N/A
C25: =IF(H26="",IF(H25="","",C24+1),IF(H25="","",C24+1)) | D25: EXPLORACIÓN | E25: =IF(H25="","",H25) | F25: =IF(C25="","",HYPERLINK("#'2026'!"&G25,"Ir a la actividad"&H25)) | G25: {=ADDRESS(MATCH($H25,'año26'!F:F,0),COLUMN('año26'!F:F))} -> #N/A
C26: =IF(H27="",IF(H26="","",C25+1),IF(H26="","",C25+1)) | D26: EXPLORACIÓN | E26: =IF(H26="","",H26) | F26: =IF(C26="","",HYPERLINK("#'2026'!"&G26,"Ir a la actividad"&H26)) | G26: {=ADDRESS(MATCH($H26,'año26'!F:F,0),COLUMN('año26'!F:F))} -> #N/A
C27: =IF(H28="",IF(H27="","",C26+1),IF(H27="","",C26+1)) | D27: EXPLORACIÓN | E27: =IF(H27="","",H27) | F27: =IF(C27="","",HYPERLINK("#'2026'!"&G27,"Ir a la actividad"&H27)) | G27: {=ADDRESS(MATCH($H27,'año26'!F:F,0),COLUMN('año26'!F:F))} -> #N/A
C28: =IF(H29="",IF(H28="","",C27+1),IF(H28="","",C27+1)) | E28: =IF(H28="","",H28) | F28: =IF(C28="","",HYPERLINK("#'2026'!"&G28,"Ir a la actividad"&H28)) | G28: {=ADDRESS(MATCH($H28,'año26'!F:F,0),COLUMN('año26'!F:F))} -> #N/A
C29: =IF(H30="",IF(H29="","",C28+1),IF(H29="","",C28+1)) | E29: =IF(H29="","",H29) | F29: =IF(C29="","",HYPERLINK("#'2026'!"&G29,"Ir a la actividad"&H29)) | G29: {=ADDRESS(MATCH($H29,'año26'!F:F,0),COLUMN('año26'!F:F))} -> #N/A
C30: =IF(H31="",IF(H30="","",C29+1),IF(H30="","",C29+1)) | E30: =IF(H30="","",H30) | F30: =IF(C30="","",HYPERLINK("#'2026'!"&G30,"Ir a la actividad"&H30)) | G30: {=ADDRESS(MATCH($H30,'año26'!F:F,0),COLUMN('año26'!F:F))} -> #N/A
C31: =IF(H32="",IF(H31="","",C30+1),IF(H31="","",C30+1)) | E31: =IF(H31="","",H31) | F31: =IF(C31="","",HYPERLINK("#'2026'!"&G31,"Ir a la actividad"&H31)) | G31: {=ADDRESS(MATCH($H31,'año26'!F:F,0),COLUMN('año26'!F:F))} -> #N/A
C32: =IF(H33="",IF(H32="","",C31+1),IF(H32="","",C31+1)) | E32: =IF(H32="","",H32) | F32: =IF(C32="","",HYPERLINK("#'2026'!"&G32,"Ir a la actividad"&H32)) | G32: {=ADDRESS(MATCH($H32,'año26'!F:F,0),COLUMN('año26'!F:F))} -> #N/A
C33: =IF(H34="",IF(H33="","",C32+1),IF(H33="","",C32+1)) | E33: =IF(H33="","",H33) | F33: =IF(C33="","",HYPERLINK("#'2026'!"&G33,"Ir a la actividad"&H33)) | G33: {=ADDRESS(MATCH($H33,'año26'!F:F,0),COLUMN('año26'!F:F))} -> #N/A
C34: =IF(H35="",IF(H34="","",C33+1),IF(H34="","",C33+1)) | E34: =IF(H34="","",H34) | F34: =IF(C34="","",HYPERLINK("#'2026'!"&G34,"Ir a la actividad"&H34)) | G34: {=ADDRESS(MATCH($H34,'año26'!F:F,0),COLUMN('año26'!F:F))} -> #N/A
C35: =IF(H36="",IF(H35="","",C34+1),IF(H35="","",C34+1)) | E35: =IF(H35="","",H35) | F35: =IF(C35="","",HYPERLINK("#'2026'!"&G35,"Ir a la actividad"&H35)) | G35: {=ADDRESS(MATCH($H35,'año26'!F:F,0),COLUMN('año26'!F:F))} -> #N/A
C36: =IF(H37="",IF(H36="","",C35+1),IF(H36="","",C35+1)) | E36: =IF(H36="","",H36) | F36: =IF(C36="","",HYPERLINK("#'2026'!"&G36,"Ir a la actividad"&H36)) | G36: {=ADDRESS(MATCH($H36,'año26'!F:F,0),COLUMN('año26'!F:F))} -> #N/A
C37: =IF(H38="",IF(H37="","",C36+1),IF(H37="","",C36+1)) | E37: =IF(H37="","",H37) | F37: =IF(C37="","",HYPERLINK("#'2026'!"&G37,"Ir a la actividad"&H37)) | G37: {=ADDRESS(MATCH($H37,'año26'!F:F,0),COLUMN('año26'!F:F))} -> #N/A
C38: =IF(H39="",IF(H38="","",C37+1),IF(H38="","",C37+1)) | E38: =IF(H38="","",H38) | F38: =IF(C38="","",HYPERLINK("#'2026'!"&G38,"Ir a la actividad"&H38)) | G38: {=ADDRESS(MATCH($H38,'año26'!F:F,0),COLUMN('año26'!F:F))} -> #N/A
C39: =IF(H40="",IF(H39="","",C38+1),IF(H39="","",C38+1)) | E39: =IF(H39="","",H39) | F39: =IF(C39="","",HYPERLINK("#'2026'!"&G39,"Ir a la actividad"&H39)) | G39: {=ADDRESS(MATCH($H39,'año26'!F:F,0),COLUMN('año26'!F:F))} -> #N/A
... C196: =IF(H197="",IF(H196="","",C195+1),IF(H196="","",C195+1)) | E196: =IF(H196="","",H196) | F196: =IF(C196="","",HYPERLINK("#'2026'!"&G196,"Ir a la actividad"&H196)) | G196: {=ADDRESS(MATCH($H196,'año26'!F:F,0),COLUMN('año26'!F:F))} -> #N/A

Sheet 2024
H2: MATRIZ DE IDENTIFICACIÓN DE PELIGROS Y VALORACIÓN DE RIESGOS Y DETERMINACIÓN DE CONTROLES | AH2: CODIGO COL-HSEQ-FT-210 EMISIÓN 13-07-2015 VIGENCIA 31-05-2018 VERSIÓN 4 PÁGINA 1 de 1 | AW2: Factor de riesgo | AY2: Biológico | AZ2: Físico | BA2: Químico | BB2: Psicosocial | BC2: Biomecánicos | BD2: Condiciones de seguridad | BE2: Fenómenos naturales
B3: Proceso Evaluado: | F3: Perforación | AH3: EXTREMO | AI3: Vice-Presidentes y/o COO | AP3: Bajo | AQ3: CONSECUENCIA | AR3: 4 Crítico | AS3: 4 | AT3: 8 | AU3: 12 | AV3: 16
B4: Categoría del Riesgo: | F4: Personas, Medio ambiente, Activos y Activos & Riesgo Financiero | AH4: ALTO | AI4: Gerente de Departamento | AP4: Medio | AR4: 3 Serio | AS4: 3 | AT4: 6 | AU4: 9 | AV4: 12
B5: Alcance de la evaluación: | F5: Actualización matriz de Identificación de peligros, valoración de riesgos y determinacion de controles para las actividades de Perforación | AH5: MEDIO | AI5: Superintendente, Líder de operaciones, Etc. | AP5: Alto | AR5: 2 Moderado | AS5: 2 | AT5: 4 | AU5: 6 | AV5: 8
B6: Responsable de Actualización: | F6: Rafael Bermeo / Sebastian Moyano ( Ing Operaciones) / Nidia López Ospina (Gestiones integrales HSEQ) / Henry Tocaruncho (Gerente HS) | AH6: BAJO | AI6: Autoridad de área | AP6: Extremo | AR6: 1 Menor | AS6: 1 | AT6: 2 | AU6: 3 | AV6: 4
B7: Fecha de Actualización (DD/MM/AAAA): | F7: 29/05/2021; 15/06/2022; 26/06/2023, 26/06/2024 | AS7: 1 Remoto | AT7: 2 Improbable | AU7: 3 Probable | AV7: 4 Frecuente
AS8: PROBABILIDAD
B9: No. | C9: AÑO | D9: Estación | E9: Actividad | F9: Tárea | G9: Área / Equipo | H9: PELIGRO - Descripción | I9: PELIGRO -Tipo | J9: PELIGRO -Iconografia | K9: PELIGRO - Clasificación | L9: Consecuencias (AT/EL) | M9: TAREA - Rutinaria | N9: TAREA (Interna - ERutinariaterna) | O9: Numero de personas expuestas - Directos | P9: Numero de personas expuestas - Contratistas | Q9: Numero de personas expuestas - Visitantes, Clientes, autoridades | R9: Horas de exposición (En relación con las 24 horas al día) | S9: CARGOS O PARTES INTERESADAS APLICABLES | T9: CONTROLES EXISTENTES - Fuente | U9: CONTROLES EXISTENTES - Medio | V9: CONTROLES EXISTENTES - Individuo | W9: VALORACION DE RIESGO - C | X9: VALORACION DE RIESGO - Categoría | Y9: VALORACION DE RIESGO -p | Z9: Nivel de riesgo | AA9: ERutinariaistencia de requisitos legales | AB9: CONTROLES (TRATAMIENTO DEL RIESGO Y PLANES ATENUANTES) - ELIMINACIÓN | AC9: CONTROLES (TRATAMIENTO DEL RIESGO Y PLANES ATENUANTES) - SUSTITUCIÓN | AD9: CONTROLES (TRATAMIENTO DEL RIESGO Y PLANES ATENUANTES) - CONTROLES DE INGENIERIA | AE9: CONTROLES (TRATAMIENTO DEL RIESGO Y PLANES ATENUANTES) - CONTROLES ADMINISTRATIVOS / SEÑALIZACIÓN | AF9: CONTROLES (TRATAMIENTO DEL RIESGO Y PLANES ATENUANTES) - ELEMENTOS DE PROTECCIÓN PERSONAL | AG9: Compilado de controles | AH9: RESPONSABLE DE EJECUTAR LA ACCION | AI9: VALORACION DEL RIESGO RESULTANTE CON CONTROLES (Riesgo residual) - C | AJ9: VALORACION DEL RIESGO RESULTANTE CON CONTROLES (Riesgo residual) - Categoría | AK9: VALORACION DEL RIESGO RESULTANTE CON CONTROLES (Riesgo residual) - p | AL9: VALORACION DEL RIESGO RESULTANTE CON CONTROLES (Riesgo residual) - Nivel de riesgo | AM9: VALORACION DEL RIESGO RESULTANTE CON CONTROLES (Riesgo residual) - INTERPRETACIÓN DEL RIESGO | AN9: EFICACIA DE LAS MEDIDAS DE CONTROL Registro de accidentes, casi accidentes o enfermedades generados en el periodo evaluado. | AO9: Eficaz | AP9: Comprensión Riesgo | AQ9: Nivel del Riesgo
B10: 1 | C10: 2024 | D10: Campos Parex | E10: MOVILIZACIÓN Y DESMOVILIZACIÓN | F10: Inspección de vía y nueva locación: Recorridos a pie / Supervisión en campo/ inspecciones/ Interaccion con la comunidad / Desplazamiento en vehículos | G10: Ruta de Movilización y Nueva locación | H10: Atropellos o golpes con vehículos | I10: Condiciones_de_seguridad | J10: =_xlfn.XLOOKUP(año24[[#This Row],[PELIGRO -Tipo]], Tabla12[Calsificación], Tabla12[Imagen]) -> #VALUE! | K10: 6.5 Accidentes de transito | L10: AT | M10: Rutinaria | N10: Interna | O10: 2 | P10: 4 | Q10: 2 | R10: 8 | S10: Contratistas | T10: Sistemas de seguridad del Vehículo (cinturón de seguridad, airbags, apoya cabezas, llantas) Sistema de monitoreo de velocidad acorde a la legislación | U10: Inspecciones de seguridad Plan de movilizaciones Señalización Controlador vial | V10: * Plan estratégico de seguridad via-PEVS * Control de contratistas de servicios de transporte * Anexo HSEQ para contratistas * Plan de Emergencias | W10: 3 Serio | X10: Personas | Y10: 3 Probable | Z10: =INDEX($AS$3:$AV$6,MATCH($W10,$AR$3:$AR$6,FALSE),MATCH($Y10,AS$7:$AV$7,FALSE)) -> 9 | AA10: Si (Ver matriz de requisitos legales) | AB10: Ninguna | AC10: Ninguna | AD10: Sistemas de seguridad del Vehículo (cinturón de seguridad, airbags, apoya cabezas, llantas) | AE10: Continuar con los controles implemetados: *Seguimiento cumplimiento del PESV * Evaluación de desempeño de cotratistas | AF10: Ver matriz de EPP | AG10: ="Eliminación del riesgo:"&año24[[#This Row],[CONTROLES (TRATAMIENTO DEL RIESGO Y PLANES ATENUANTES) - ELIMINACIÓN]]&"Sustitución del riesgo; "&año24[[#This Row],[CONTROLES (TRATAMIENTO DEL RIESGO Y PLANES ATENUANTES) - SUSTITUCIÓN]]&"Controles de Ingenieria; "&año24[[#This Row],[CONTROLES (TRATAMIENTO DEL RIESGO Y PLANES ATENUANTES) - CONTROLES DE INGENIERIA]]&" Controles administrativos; "&año24[[#This Row],[CONTROLES (TRATAMIENTO DEL RIESGO Y PLANES ATENUANTES) - CONTROLES ADMINISTRATIVOS / SEÑALIZACIÓN]]&"Controles de EPP; "&año24[[#This Row],[CONTROLES (TRATAMIENTO DEL RIESGO Y PLANES ATENUANTES) - ELEMENTOS DE PROTECCIÓN PERSONAL]] -> Eliminación del riesgo:NingunaSustitución del riesgo; NingunaControles de Ingenieria; Sistemas de seguridad del Vehículo (cinturón de seguridad, airbags, apoya cabezas, llantas) Controles administrativos; Continuar con los controles implemetados: *Seguimiento cumplimiento del PESV * Evaluación de desempeño de cotratistas Controles de EPP; Ver matriz de EPP | AH10: HS Parex Contratista | AI10: 2 Moderado | AJ10: Personas | AK10: 2 Improbable | AL10: =INDEX($AS$3:$AV$6,MATCH($AI10,$AR$3:$AR$6,FALSE),MATCH($AK10,$AS$7:$AV$7,FALSE)) -> 4 | AM10: =IF(año24[[#This Row],[VALORACION DEL RIESGO RESULTANTE CON CONTROLES (Riesgo residual) - Nivel de riesgo]]<=3,"Bajo",IF(año24[[#This Row],[VALORACION DEL RIESGO RESULTANTE CON CONTROLES (Riesgo residual) - Nivel de riesgo]]<=6,"Medio",IF(año24[[#This Row],[VALORACION DEL RIESGO RESULTANTE CON CONTROLES (Riesgo residual) - Nivel de riesgo]]<=12,"Alto","Extremo"))) -> Medio | AO10: =IF(AL10<=4,"SI",IF(AL10>=5,"NO")) -> SI | AP10: ="El nivel del riesgo es"&" "&año24[[#This Row],[VALORACION DEL RIESGO RESULTANTE CON CONTROLES (Riesgo residual) - INTERPRETACIÓN DEL RIESGO]]&" siendo las principales consecuencias las siguientes; "&año24[[#This Row],[Consecuencias (AT/EL)]] -> El nivel del riesgo es Medio siendo las principales consecuencias las siguientes; AT | AQ10: =_xlfn.XLOOKUP(año24[[#This Row],[VALORACION DEL RIESGO RESULTANTE CON CONTROLES (Riesgo residual) - INTERPRETACIÓN DEL RIESGO]], Nivel[Calsificación], Nivel[Imagen]) -> #VALUE!
B11: 2 | C11: 2024 | D11: Campos Parex | E11: MOVILIZACIÓN Y DESMOVILIZACIÓN | F11: Inspección de vía y nueva locación: Recorridos a pie / Supervisión en campo/ inspecciones/ Interaccion con la comunidad / Desplazamiento en vehículos | G11: Ruta de Movilización y Nueva locación | H11: Lluvias, tormentas eléctricas | I11: Fenómenos_naturales | J11: =_xlfn.XLOOKUP(año24[[#This Row],[PELIGRO -Tipo]], Tabla12[Calsificación], Tabla12[Imagen]) -> #VALUE! | K11: 7.6 Precipitaciones | L11: AT | M11: Rutinaria | N11: Externa | O11: 2 | P11: 4 | Q11: 2 | R11: 1 | S11: Contratistas | T11: Ninguna | U11: Señalización Layout de la locación Sistema de alarma Detector de tormentas Pararrayos Brigada de emergencias | V11: Uso de EPP (Dotación de invierno) Charlas Informativas | W11: 3 Serio | X11: Personas | Y11: 2 Improbable | Z11: =INDEX($AS$3:$AV$6,MATCH($W11,$AR$3:$AR$6,FALSE),MATCH($Y11,AS$7:$AV$7,FALSE)) -> 6 | AA11: Si (Ver matriz de requisitos legales) | AB11: Ninguna | AC11: Ninguna | AD11: Puesta a tierra de equipos en la locación | AE11: Continuar con los controles implemetados: * Plan de emergencias *Unidad de Respuesta a Emergencias (URE) | AF11: Ver matriz de EPP | AG11: ="Eliminación del riesgo:"&año24[[#This Row],[CONTROLES (TRATAMIENTO DEL RIESGO Y PLANES ATENUANTES) - ELIMINACIÓN]]&"Sustitución del riesgo; "&año24[[#This Row],[CONTROLES (TRATAMIENTO DEL RIESGO Y PLANES ATENUANTES) - SUSTITUCIÓN]]&"Controles de Ingenieria; "&año24[[#This Row],[CONTROLES (TRATAMIENTO DEL RIESGO Y PLANES ATENUANTES) - CONTROLES DE INGENIERIA]]&" Controles administrativos; "&año24[[#This Row],[CONTROLES (TRATAMIENTO DEL RIESGO Y PLANES ATENUANTES) - CONTROLES ADMINISTRATIVOS / SEÑALIZACIÓN]]&"Controles de EPP; "&año24[[#This Row],[CONTROLES (TRATAMIENTO DEL RIESGO Y PLANES ATENUANTES) - ELEMENTOS DE PROTECCIÓN PERSONAL]] -> Eliminación del riesgo:NingunaSustitución del riesgo; NingunaControles de Ingenieria; Puesta a tierra de equipos en la locación Controles administrativos; Continuar con los controles implemetados: * Plan de emergencias *Unidad de Respuesta a Emergencias (URE)Controles de EPP; Ver matriz de EPP | AH11: HS Parex Contratista | AI11: 3 Serio | AJ11: Personas | AK11: 1 Remoto | AL11: =INDEX($AS$3:$AV$6,MATCH($AI11,$AR$3:$AR$6,FALSE),MATCH($AK11,$AS$7:$AV$7,FALSE)) -> 3 | AM11: =IF(año24[[#This Row],[VALORACION DEL RIESGO RESULTANTE CON CONTROLES (Riesgo residual) - Nivel de riesgo]]<=3,"Bajo",IF(año24[[#This Row],[VALORACION DEL RIESGO RESULTANTE CON CONTROLES (Riesgo residual) - Nivel de riesgo]]<=6,"Medio",IF(año24[[#This Row],[VALORACION DEL RIESGO RESULTANTE CON CONTROLES (Riesgo residual) - Nivel de riesgo]]<=12,"Alto","Extremo"))) -> Bajo | AO11: =IF(AL11<=4,"SI",IF(AL11>=5,"NO")) -> SI | AP11: ="El nivel del riesgo es"&" "&año24[[#This Row],[VALORACION DEL RIESGO RESULTANTE CON CONTROLES (Riesgo residual) - INTERPRETACIÓN DEL RIESGO]]&" siendo las principales consecuencias las siguientes; "&año24[[#This Row],[Consecuencias (AT/EL)]] -> El nivel del riesgo es Bajo siendo las principales consecuencias las siguientes; AT | AQ11: =_xlfn.XLOOKUP(año24[[#This Row],[VALORACION DEL RIESGO RESULTANTE CON CONTROLES (Riesgo residual) - INTERPRETACIÓN DEL RIESGO]], Nivel[Calsificación], Nivel[Imagen]) -> #VALUE!
B12: 3 | C12: 2024 | D12: Campos Parex | E12: MOVILIZACIÓN Y DESMOVILIZACIÓN | F12: Inspección de vía y nueva locación: Recorridos a pie / Supervisión en campo/ inspecciones/ Interaccion con la comunidad / Desplazamiento en vehículos | G12: Ruta de Movilización y Nueva locación | H12: Características del grupo social de trabajo (Relaciones, cohesión, calidad de interacciones, trabajo en equipo) Jornadas de trabajo (pausas, trabajo nocturno, rotación, horas extras, descanso) | I12: Psicosocial | J12: =_xlfn.XLOOKUP(año24[[#This Row],[PELIGRO -Tipo]], Tabla12[Calsificación], Tabla12[Imagen]) -> #VALUE! | K12: 4.4 Características del grupo social de trabajo | L12: EL | M12: Rutinaria | N12: Interna | O12: 2 | P12: 4 | Q12: 2 | R12: 8 | S12: Contratistas | T12: Organización del trabajo Definición de manuales de funciones y cargos | U12: Política de prevención de acoso laboral Comité de convivencia laboral | V12: *Aplicación de baterías de riesgo psicosocial * Capacitación en riesgo psicosocial * PVE de Riesgo Psicosocial | W12: 2 Moderado | X12: Personas | Y12: 2 Improbable | Z12: =INDEX($AS$3:$AV$6,MATCH($W12,$AR$3:$AR$6,FALSE),MATCH($Y12,AS$7:$AV$7,FALSE)) -> 4 | AA12: Si (Ver matriz de requisitos legales) | AB12: Ninguna | AC12: Ninguna | AD12: Ninguna | AE12: Continuidad en la aplicación de los controles: * Seguimiento a los planes de intervención del PVE de riesgo psicosocial * Pausas activas | AF12: Ninguna | AG12: ="Eliminación del riesgo:"&año24[[#This Row],[CONTROLES (TRATAMIENTO DEL RIESGO Y PLANES ATENUANTES) - ELIMINACIÓN]]&"Sustitución del riesgo; "&año24[[#This Row],[CONTROLES (TRATAMIENTO DEL RIESGO Y PLANES ATENUANTES) - SUSTITUCIÓN]]&"Controles de Ingenieria; "&año24[[#This Row],[CONTROLES (TRATAMIENTO DEL RIESGO Y PLANES ATENUANTES) - CONTROLES DE INGENIERIA]]&" Controles administrativos; "&año24[[#This Row],[CONTROLES (TRATAMIENTO DEL RIESGO Y PLANES ATENUANTES) - CONTROLES ADMINISTRATIVOS / SEÑALIZACIÓN]]&"Controles de EPP; "&año24[[#This Row],[CONTROLES (TRATAMIENTO DEL RIESGO Y PLANES ATENUANTES) - ELEMENTOS DE PROTECCIÓN PERSONAL]] -> Eliminación del riesgo:NingunaSustitución del riesgo; NingunaControles de Ingenieria; Ninguna Controles administrativos; Continuidad en la aplicación de los controles: * Seguimiento a los planes de intervención del PVE de riesgo psicosocial * Pausas activas Controles de EPP; Ninguna | AH12: HS Parex Contratista | AI12: 1 Menor | AJ12: Personas | AK12: 2 Improbable | AL12: =INDEX($AS$3:$AV$6,MATCH($AI12,$AR$3:$AR$6,FALSE),MATCH($AK12,$AS$7:$AV$7,FALSE)) -> 2 | AM12: =IF(año24[[#This Row],[VALORACION DEL RIESGO RESULTANTE CON CONTROLES (Riesgo residual) - Nivel de riesgo]]<=3,"Bajo",IF(año24[[#This Row],[VALORACION DEL RIESGO RESULTANTE CON CONTROLES (Riesgo residual) - Nivel de riesgo]]<=6,"Medio",IF(año24[[#This Row],[VALORACION DEL RIESGO RESULTANTE CON CONTROLES (Riesgo residual) - Nivel de riesgo]]<=12,"Alto","Extremo"))) -> Bajo | AO12: =IF(AL12<=4,"SI",IF(AL12>=5,"NO")) -> SI | AP12: ="El nivel del riesgo es"&" "&año24[[#This Row],[VALORACION DEL RIESGO RESULTANTE CON CONTROLES (Riesgo residual) - INTERPRETACIÓN DEL RIESGO]]&" siendo las principales consecuencias las siguientes; "&año24[[#This Row],[Consecuencias (AT/EL)]] -> El nivel del riesgo es Bajo siendo las principales consecuencias las siguientes; EL | AQ12: =_xlfn.XLOOKUP(año24[[#This Row],[VALORACION DEL RIESGO RESULTANTE CON CONTROLES (Riesgo residual) - INTERPRETACIÓN DEL RIESGO]], Nivel[Calsificación], Nivel[Imagen]) -> #VALUE!
B13: 4 | C13: 2024 | D13: Campos Parex | E13: MOVILIZACIÓN Y DESMOVILIZACIÓN | F13: Inspección de vía y nueva locación: Recorridos a pie / Supervisión en campo/ inspecciones/ Interaccion con la comunidad / Desplazamiento en vehículos | G13: Ruta de Movilización y Nueva locación | H13: Condiciones de la tarea (carga mental, demandas emocionales, sistemas de control, etc.) | I13: Psicosocial | J13: =_xlfn.XLOOKUP(año24[[#This Row],[PELIGRO -Tipo]], Tabla12[Calsificación], Tabla12[Imagen]) -> #VALUE! | K13: 4.3 Condiciones de la tarea | L13: EL | M13: Rutinaria | N13: Interna | O13: 2 | P13: 4 | Q13: 2 | R13: 8 | S13: Contratistas | T13: Organización del trabajo Definición de manuales de funciones y cargos | U13: Política de prevención de acoso laboral Comité de convivencia laboral | V13: *Aplicación de baterías de riesgo psicosocial * Capacitación en riesgo psicosocial * PVE de Riesgo Psicosocial | W13: 2 Moderado | X13: Personas | Y13: 2 Improbable | Z13: =INDEX($AS$3:$AV$6,MATCH($W13,$AR$3:$AR$6,FALSE),MATCH($Y13,AS$7:$AV$7,FALSE)) -> 4 | AA13: Si (Ver matriz de requisitos legales) | AB13: Ninguna | AC13: Ninguna | AD13: Ninguna | AE13: Continuidad en la aplicación de los controles: * Seguimiento a los planes de intervención del PVE de riesgo psicosocial * Pausas activas | AF13: Ninguna | AG13: ="Eliminación del riesgo:"&año24[[#This Row],[CONTROLES (TRATAMIENTO DEL RIESGO Y PLANES ATENUANTES) - ELIMINACIÓN]]&"Sustitución del riesgo; "&año24[[#This Row],[CONTROLES (TRATAMIENTO DEL RIESGO Y PLANES ATENUANTES) - SUSTITUCIÓN]]&"Controles de Ingenieria; "&año24[[#This Row],[CONTROLES (TRATAMIENTO DEL RIESGO Y PLANES ATENUANTES) - CONTROLES DE INGENIERIA]]&" Controles administrativos; "&año24[[#This Row],[CONTROLES (TRATAMIENTO DEL RIESGO Y PLANES ATENUANTES) - CONTROLES ADMINISTRATIVOS / SEÑALIZACIÓN]]&"Controles de EPP; "&año24[[#This Row],[CONTROLES (TRATAMIENTO DEL RIESGO Y PLANES ATENUANTES) - ELEMENTOS DE PROTECCIÓN PERSONAL]] -> Eliminación del riesgo:NingunaSustitución del riesgo; NingunaControles de Ingenieria; Ninguna Controles administrativos; Continuidad en la aplicación de los controles: * Seguimiento a los planes de intervención del PVE de riesgo psicosocial * Pausas activas Controles de EPP; Ninguna | AH13: HS Parex Contratista | AI13: 1 Menor | AJ13: Personas | AK13: 2 Improbable | AL13: =INDEX($AS$3:$AV$6,MATCH($AI13,$AR$3:$AR$6,FALSE),MATCH($AK13,$AS$7:$AV$7,FALSE)) -> 2 | AM13: =IF(año24[[#This Row],[VALORACION DEL RIESGO RESULTANTE CON CONTROLES (Riesgo residual) - Nivel de riesgo]]<=3,"Bajo",IF(año24[[#This Row],[VALORACION DEL RIESGO RESULTANTE CON CONTROLES (Riesgo residual) - Nivel de riesgo]]<=6,"Medio",IF(año24[[#This Row],[VALORACION DEL RIESGO RESULTANTE CON CONTROLES (Riesgo residual) - Nivel de riesgo]]<=12,"Alto","Extremo"))) -> Bajo | AO13: =IF(AL13<=4,"SI",IF(AL13>=5,"NO")) -> SI | AP13: ="El nivel del riesgo es"&" "&año24[[#This Row],[VALORACION DEL RIESGO RESULTANTE CON CONTROLES (Riesgo residual) - INTERPRETACIÓN DEL RIESGO]]&" siendo las principales consecuencias las siguientes; "&año24[[#This Row],[Consecuencias (AT/EL)]] -> El nivel del riesgo es Bajo siendo las principales consecuencias las siguientes; EL | AQ13: =_xlfn.XLOOKUP(año24[[#This Row],[VALORACION DEL RIESGO RESULTANTE CON CONTROLES (Riesgo residual) - INTERPRETACIÓN DEL RIESGO]], Nivel[Calsificación], Nivel[Imagen]) -> #VALUE!
B14: 5 | C14: 2024 | D14: Campos Parex | E14: MOVILIZACIÓN Y DESMOVILIZACIÓN | F14: Inspección de vía y nueva locación: Recorridos a pie / Supervisión en campo/ inspecciones/ Interaccion con la comunidad / Desplazamiento en vehículos | G14: Ruta de Movilización y Nueva locación | H14: Almacenamiento, manipulación y contacto con sustancias químicas para limpieza y desinfección de superficies | I14: Químico | J14: =_xlfn.XLOOKUP(año24[[#This Row],[PELIGRO -Tipo]], Tabla12[Calsificación], Tabla12[Imagen]) -> #VALUE! | K14: 3.4 Líquidos, rocíos | L14: AT/EL | M14: Rutinaria | N14: Interna | O14: 2 | P14: 4 | Q14: 2 | R14: 8 | S14: Contratistas | T14: Identificación de peligrosidad con Sistema Globalmente armonizado | U14: Programa de Higiene Ocupacional (Mediciones de higiene según cronoggrama) | V14: Programa de gestión de riesgo químico EPP Exámenes médicos ocupacionales Capacitación en riesgo químico | W14: 2 Moderado | X14: Personas | Y14: 3 Probable | Z14: =INDEX($AS$3:$AV$6,MATCH($W14,$AR$3:$AR$6,FALSE),MATCH($Y14,AS$7:$AV$7,FALSE)) -> 6 | AA14: Si (Ver matriz de requisitos legales) | AB14: Ninguna | AC14: Ninguna | AD14: Ninguna | AE14: Continuidad a los controles implementados: Seguimiento al programa de gestión del riesgo químico Programa de Seguridad Basada en el Comportamiento | AF14: Ver matriz de EPP | AG14: ="Eliminación del riesgo:"&año24[[#This Row],[CONTROLES (TRATAMIENTO DEL RIESGO Y PLANES ATENUANTES) - ELIMINACIÓN]]&"Sustitución del riesgo; "&año24[[#This Row],[CONTROLES (TRATAMIENTO DEL RIESGO Y PLANES ATENUANTES) - SUSTITUCIÓN]]&"Controles de Ingenieria; "&año24[[#This Row],[CONTROLES (TRATAMIENTO DEL RIESGO Y PLANES ATENUANTES) - CONTROLES DE INGENIERIA]]&" Controles administrativos; "&año24[[#This Row],[CONTROLES (TRATAMIENTO DEL RIESGO Y PLANES ATENUANTES) - CONTROLES ADMINISTRATIVOS / SEÑALIZACIÓN]]&"Controles de EPP; "&año24[[#This Row],[CONTROLES (TRATAMIENTO DEL RIESGO Y PLANES ATENUANTES) - ELEMENTOS DE PROTECCIÓN PERSONAL]] -> Eliminación del riesgo:NingunaSustitución del riesgo; NingunaControles de Ingenieria; Ninguna Controles administrativos; Continuidad a los controles implementados: Seguimiento al programa de gestión del riesgo químico Programa de Seguridad Basada en el ComportamientoControles de EPP; Ver matriz de EPP | AH14: HS Parex Contratista | AI14: 2 Moderado | AJ14: Personas | AK14: 2 Improbable | AL14: =INDEX($AS$3:$AV$6,MATCH($AI14,$AR$3:$AR$6,FALSE),MATCH($AK14,$AS$7:$AV$7,FALSE)) -> 4 | AM14: =IF(año24[[#This Row],[VALORACION DEL RIESGO RESULTANTE CON CONTROLES (Riesgo residual) - Nivel de riesgo]]<=3,"Bajo",IF(año24[[#This Row],[VALORACION DEL RIESGO RESULTANTE CON CONTROLES (Riesgo residual) - Nivel de riesgo]]<=6,"Medio",IF(año24[[#This Row],[VALORACION DEL RIESGO RESULTANTE CON CONTROLES (Riesgo residual) - Nivel de riesgo]]<=12,"Alto","Extremo"))) -> Medio | AO14: =IF(AL14<=4,"SI",IF(AL14>=5,"NO")) -> SI | AP14: ="El nivel del riesgo es"&" "&año24[[#This Row],[VALORACION DEL RIESGO RESULTANTE CON CONTROLES (Riesgo residual) - INTERPRETACIÓN DEL RIESGO]]&" siendo las principales consecuencias las siguientes; "&año24[[#This Row],[Consecuencias (AT/EL)]] -> El nivel del riesgo es Medio siendo las principales consecuencias las siguientes; AT/EL | AQ14: =_xlfn.XLOOKUP(año24[[#This Row],[VALORACION DEL RIESGO RESULTANTE CON CONTROLES (Riesgo residual) - INTERPRETACIÓN DEL RIESGO]], Nivel[Calsificación], Nivel[Imagen]) -> #VALUE!
B15: 6 | C15: 2024 | D15: Campos Parex | E15: MOVILIZACIÓN Y DESMOVILIZACIÓN | F15: Inspección de vía y nueva locación: Recorridos a pie / Supervisión en campo/ inspecciones/ Interaccion con la comunidad / Desplazamiento en vehículos | G15: Ruta de Movilización y Nueva locación | H15: Actos y comportamientos inseguros, por no cumplir políticas, estándares y procedimietos de trabajo | I15: Psicosocial | J15: =_xlfn.XLOOKUP(año24[[#This Row],[PELIGRO -Tipo]], Tabla12[Calsificación], Tabla12[Imagen]) -> #VALUE! | K15: 4.2 Características de la organización del trabajo | L15: EL | M15: Rutinaria | N15: Interna | O15: 2 | P15: 4 | Q15: 2 | R15: 8 | S15: Contratistas | T15: Organización del trabajo Definición de manuales de funciones y cargos | U15: Política de prevención de acoso laboral Comité de convivencia laboral | V15: *Aplicación de baterías de riesgo psicosocial * Capacitación en riesgo psicosocial * PVE de Riesgo Psicosocial | W15: 2 Moderado | X15: Personas | Y15: 2 Improbable | Z15: =INDEX($AS$3:$AV$6,MATCH($W15,$AR$3:$AR$6,FALSE),MATCH($Y15,AS$7:$AV$7,FALSE)) -> 4 | AA15: Si (Ver matriz de requisitos legales) | AB15: Ninguna | AC15: Ninguna | AD15: Ninguna | AE15: Continuidad en la aplicación de los controles: * Seguimiento a los planes de intervención del PVE de riesgo psicosocial * Pausas activas | AF15: Ninguna | AG15: ="Eliminación del riesgo:"&año24[[#This Row],[CONTROLES (TRATAMIENTO DEL RIESGO Y PLANES ATENUANTES) - ELIMINACIÓN]]&"Sustitución del riesgo; "&año24[[#This Row],[CONTROLES (TRATAMIENTO DEL RIESGO Y PLANES ATENUANTES) - SUSTITUCIÓN]]&"Controles de Ingenieria; "&año24[[#This Row],[CONTROLES (TRATAMIENTO DEL RIESGO Y PLANES ATENUANTES) - CONTROLES DE INGENIERIA]]&" Controles administrativos; "&año24[[#This Row],[CONTROLES (TRATAMIENTO DEL RIESGO Y PLANES ATENUANTES) - CONTROLES ADMINISTRATIVOS / SEÑALIZACIÓN]]&"Controles de EPP; "&año24[[#This Row],[CONTROLES (TRATAMIENTO DEL RIESGO Y PLANES ATENUANTES) - ELEMENTOS DE PROTECCIÓN PERSONAL]] -> Eliminación del riesgo:NingunaSustitución del riesgo; NingunaControles de Ingenieria; Ninguna Controles administrativos; Continuidad en la aplicación de los controles: * Seguimiento a los planes de intervención del PVE de riesgo psicosocial * Pausas activas Controles de EPP; Ninguna | AH15: HS Parex Contratista | AI15: 1 Menor | AJ15: Personas | AK15: 2 Improbable | AL15: =INDEX($AS$3:$AV$6,MATCH($AI15,$AR$3:$AR$6,FALSE),MATCH($AK15,$AS$7:$AV$7,FALSE)) -> 2 | AM15: =IF(año24[[#This Row],[VALORACION DEL RIESGO RESULTANTE CON CONTROLES (Riesgo residual) - Nivel de riesgo]]<=3,"Bajo",IF(año24[[#This Row],[VALORACION DEL RIESGO RESULTANTE CON CONTROLES (Riesgo residual) - Nivel de riesgo]]<=6,"Medio",IF(año24[[#This Row],[VALORACION DEL RIESGO RESULTANTE CON CONTROLES (Riesgo residual) - Nivel de riesgo]]<=12,"Alto","Extremo"))) -> Bajo | AO15: =IF(AL15<=4,"SI",IF(AL15>=5,"NO")) -> SI | AP15: ="El nivel del riesgo es"&" "&año24[[#This Row],[VALORACION DEL RIESGO RESULTANTE CON CONTROLES (Riesgo residual) - INTERPRETACIÓN DEL RIESGO]]&" siendo las principales consecuencias las siguientes; "&año24[[#This Row],[Consecuencias (AT/EL)]] -> El nivel del riesgo es Bajo siendo las principales consecuencias las siguientes; EL | AQ15: =_xlfn.XLOOKUP(año24[[#This Row],[VALORACION DEL RIESGO RESULTANTE CON CONTROLES (Riesgo residual) - INTERPRETACIÓN DEL RIESGO]], Nivel[Calsificación], Nivel[Imagen]) -> #VALUE!
B16: 7 | C16: 2024 | D16: Campos Parex | E16: MOVILIZACIÓN Y DESMOVILIZACIÓN | F16: Inspección de vía y nueva locación: Recorridos a pie / Supervisión en campo/ inspecciones/ Interaccion con la comunidad / Desplazamiento en vehículos | G16: Ruta de Movilización y Nueva locación | H16: Radiación no ionizante (Exposición a rayos solares) | I16: Físico | J16: =_xlfn.XLOOKUP(año24[[#This Row],[PELIGRO -Tipo]], Tabla12[Calsificación], Tabla12[Imagen]) -> #VALUE! | K16: 2.7 Radiaciones No ionizantes | L16: EL | M16: Rutinaria | N16: Interna | O16: 2 | P16: 4 | Q16: 2 | R16: 4 | S16: Contratistas | T16: Ninguna | U16: Ninguna | V16: Hidratación. Uso de bloqueador solar Examen Ocupacional con énfasis dermatológico | W16: 2 Moderado | X16: Personas | Y16: 3 Probable | Z16: =INDEX($AS$3:$AV$6,MATCH($W16,$AR$3:$AR$6,FALSE),MATCH($Y16,AS$7:$AV$7,FALSE)) -> 6 | AA16: Si (Ver matriz de requisitos legales) | AB16: Ninguna | AC16: Ninguna | AD16: Ninguna | AE16: Mantener controles existentes: Hidratación. Uso de bloqueador solar Examen Ocupacional con énfasis dermatológico Evitar la exposición directa a la luz solar dos horas antes y dos horas después del medio día. Capacitación en lesiones de piel | AF16: Ver matriz de EPP | AG16: ="Eliminación del riesgo:"&año24[[#This Row],[CONTROLES (TRATAMIENTO DEL RIESGO Y PLANES ATENUANTES) - ELIMINACIÓN]]&"Sustitución del riesgo; "&año24[[#This Row],[CONTROLES (TRATAMIENTO DEL RIESGO Y PLANES ATENUANTES) - SUSTITUCIÓN]]&"Controles de Ingenieria; "&año24[[#This Row],[CONTROLES (TRATAMIENTO DEL RIESGO Y PLANES ATENUANTES) - CONTROLES DE INGENIERIA]]&" Controles administrativos; "&año24[[#This Row],[CONTROLES (TRATAMIENTO DEL RIESGO Y PLANES ATENUANTES) - CONTROLES ADMINISTRATIVOS / SEÑALIZACIÓN]]&"Controles de EPP; "&año24[[#This Row],[CONTROLES (TRATAMIENTO DEL RIESGO Y PLANES ATENUANTES) - ELEMENTOS DE PROTECCIÓN PERSONAL]] -> Eliminación del riesgo:NingunaSustitución del riesgo; NingunaControles de Ingenieria; Ninguna Controles administrativos; Mantener controles existentes: Hidratación. Uso de bloqueador solar Examen Ocupacional con énfasis dermatológico Evitar la exposición directa a la luz solar dos horas antes y dos horas después del medio día. Capacitación en lesiones de piel Controles de EPP; Ver matriz de EPP | AH16: HS Parex Contratista | AI16: 2 Moderado | AJ16: Personas | AK16: 2 Improbable | AL16: =INDEX($AS$3:$AV$6,MATCH($AI16,$AR$3:$AR$6,FALSE),MATCH($AK16,$AS$7:$AV$7,FALSE)) -> 4 | AM16: =IF(año24[[#This Row],[VALORACION DEL RIESGO RESULTANTE CON CONTROLES (Riesgo residual) - Nivel de riesgo]]<=3,"Bajo",IF(año24[[#This Row],[VALORACION DEL RIESGO RESULTANTE CON CONTROLES (Riesgo residual) - Nivel de riesgo]]<=6,"Medio",IF(año24[[#This Row],[VALORACION DEL RIESGO RESULTANTE CON CONTROLES (Riesgo residual) - Nivel de riesgo]]<=12,"Alto","Extremo"))) -> Medio | AO16: =IF(AL16<=4,"SI",IF(AL16>=5,"NO")) -> SI | AP16: ="El nivel del riesgo es"&" "&año24[[#This Row],[VALORACION DEL RIESGO RESULTANTE CON CONTROLES (Riesgo residual) - INTERPRETACIÓN DEL RIESGO]]&" siendo las principales consecuencias las siguientes; "&año24[[#This Row],[Consecuencias (AT/EL)]] -> El nivel del riesgo es Medio siendo las principales consecuencias las siguientes; EL | AQ16: =_xlfn.XLOOKUP(año24[[#This Row],[VALORACION DEL RIESGO RESULTANTE CON CONTROLES (Riesgo residual) - INTERPRETACIÓN DEL RIESGO]], Nivel[Calsificación], Nivel[Imagen]) -> #VALUE!
B17: 8 | C17: 2024 | D17: Campos Parex | E17: MOVILIZACIÓN Y DESMOVILIZACIÓN | F17: Inspección de vía y nueva locación: Recorridos a pie / Supervisión en campo/ inspecciones/ Interaccion con la comunidad / Desplazamiento en vehículos | G17: Ruta de Movilización y Nueva locación | H17: Exposición a Virus, hongos, bacterias por la presencia de animales e insectos (picaduras, mordeduras) y por plantas (toxinas o alergias). | I17: Biológico | J17: =_xlfn.XLOOKUP(año24[[#This Row],[PELIGRO -Tipo]], Tabla12[Calsificación], Tabla12[Imagen]) -> #VALUE! | K17: 1.6 Picaduras | L17: AT | M17: Rutinaria | N17: Interna | O17: 2 | P17: 4 | Q17: 2 | R17: 8 | S17: Contratistas | T17: Ninguna | U17: Inspecciones de seguridad | V17: Esquema de vacunación completo (fiebre amarilla y tétano). Suero anti-ofídico Capacitación en Riesgo Biológico | W17: 2 Moderado | X17: Personas | Y17: 3 Probable | Z17: =INDEX($AS$3:$AV$6,MATCH($W17,$AR$3:$AR$6,FALSE),MATCH($Y17,AS$7:$AV$7,FALSE)) -> 6 | AA17: Si (Ver matriz de requisitos legales) | AB17: Ninguna | AC17: Ninguna | AD17: Ninguna | AE17: Actividades de promoción y prevención riesgos de Salud Pública (fiebre amarilla, dengue y tétano) Capacitar a los trabajadores en riesgo biológico (picaduras, clases de picaduras y tipo de animales que hay presentes en la zona). Campañas para la prevención de riesgos endémicos, socialización de SIVIGILA a la población trabajadora. Poda de la periferia de la locación Mantener controles existentes: Esquema de vacunación completo (fiebre amarilla y tétano). Suero anti-ofídico Capacitación en Riesgo Biológico * Programa de Gestión Seguridad Basada en el Comportamiento | AF17: Ver matriz de EPP | AG17: ="Eliminación del riesgo:"&año24[[#This Row],[CONTROLES (TRATAMIENTO DEL RIESGO Y PLANES ATENUANTES) - ELIMINACIÓN]]&"Sustitución del riesgo; "&año24[[#This Row],[CONTROLES (TRATAMIENTO DEL RIESGO Y PLANES ATENUANTES) - SUSTITUCIÓN]]&"Controles de Ingenieria; "&año24[[#This Row],[CONTROLES (TRATAMIENTO DEL RIESGO Y PLANES ATENUANTES) - CONTROLES DE INGENIERIA]]&" Controles administrativos; "&año24[[#This Row],[CONTROLES (TRATAMIENTO DEL RIESGO Y PLANES ATENUANTES) - CONTROLES ADMINISTRATIVOS / SEÑALIZACIÓN]]&"Controles de EPP; "&año24[[#This Row],[CONTROLES (TRATAMIENTO DEL RIESGO Y PLANES ATENUANTES) - ELEMENTOS DE PROTECCIÓN PERSONAL]] -> Eliminación del riesgo:NingunaSustitución del riesgo; NingunaControles de Ingenieria; Ninguna Controles administrativos; Actividades de promoción y prevención riesgos de Salud Pública (fiebre amarilla, dengue y tétano) Capacitar a los trabajadores en riesgo biológico (picaduras, clases de picaduras y tipo de animales que hay presentes en la zona). Campañas para la prevención de riesgos endémicos, socialización de SIVIGILA a la población trabajadora. Poda de la periferia de la locación Mantener controles existentes: Esquema de vacunación completo (fiebre amarilla y tétano). Suero anti-ofídico Capacitación en Riesgo Biológico * Programa de Gestión Seguridad Basada en el ComportamientoControles de EPP; Ver matriz de EPP | AH17: HS Parex Contratista | AI17: 2 Moderado | AJ17: Personas | AK17: 2 Improbable | AL17: =INDEX($AS$3:$AV$6,MATCH($AI17,$AR$3:$AR$6,FALSE),MATCH($AK17,$AS$7:$AV$7,FALSE)) -> 4 | AM17: =IF(año24[[#This Row],[VALORACION DEL RIESGO RESULTANTE CON CONTROLES (Riesgo residual) - Nivel de riesgo]]<=3,"Bajo",IF(año24[[#This Row],[VALORACION DEL RIESGO RESULTANTE CON CONTROLES (Riesgo residual) - Nivel de riesgo]]<=6,"Medio",IF(año24[[#This Row],[VALORACION DEL RIESGO RESULTANTE CON CONTROLES (Riesgo residual) - Nivel de riesgo]]<=12,"Alto","Extremo"))) -> Medio | AO17: =IF(AL17<=4,"SI",IF(AL17>=5,"NO")) -> SI | AP17: ="El nivel del riesgo es"&" "&año24[[#This Row],[VALORACION DEL RIESGO RESULTANTE CON CONTROLES (Riesgo residual) - INTERPRETACIÓN DEL RIESGO]]&" siendo las principales consecuencias las siguientes; "&año24[[#This Row],[Consecuencias (AT/EL)]] -> El nivel del riesgo es Medio siendo las principales consecuencias las siguientes; AT | AQ17: =_xlfn.XLOOKUP(año24[[#This Row],[VALORACION DEL RIESGO RESULTANTE CON CONTROLES (Riesgo residual) - INTERPRETACIÓN DEL RIESGO]], Nivel[Calsificación], Nivel[Imagen]) -> #VALUE!
B18: 9 | C18: 2024 | D18: Campos Parex | E18: MOVILIZACIÓN Y DESMOVILIZACIÓN | F18: Inspección de vía y nueva locación: Recorridos a pie / Supervisión en campo/ inspecciones/ Interaccion con la comunidad / Desplazamiento en vehículos | G18: Ruta de Movilización y Nueva locación | H18: Exposición a agentes biológicos por contacto, transmisión aérea o hídrica | I18: Biológico | J18: =_xlfn.XLOOKUP(año24[[#This Row],[PELIGRO -Tipo]], Tabla12[Calsificación], Tabla12[Imagen]) -> #VALUE! | K18: 1.1 Virus | L18: EL | M18: Rutinaria | N18: Interna | O18: 2 | P18: 4 | Q18: 2 | R18: 8 | S18: Contratistas | V18: EPP Vacunación Charlas de PYP | W18: 2 Moderado | X18: Personas | Y18: 3 Probable | Z18: =INDEX($AS$3:$AV$6,MATCH($W18,$AR$3:$AR$6,FALSE),MATCH($Y18,AS$7:$AV$7,FALSE)) -> 6 | AA18: Si (Ver matriz de requisitos legales) | AB18: Ninguna | AC18: Ninguna | AE18: Programa de capacitacion y entrenamiento Verificacion esquema de vacunacion Instructivo practica seguro en campo exposición a riesgo biológico COL-HSE-IN-018 | AF18: Ver matriz de EPP | AG18: ="Eliminación del riesgo:"&año24[[#This Row],[CONTROLES (TRATAMIENTO DEL RIESGO Y PLANES ATENUANTES) - ELIMINACIÓN]]&"Sustitución del riesgo; "&año24[[#This Row],[CONTROLES (TRATAMIENTO DEL RIESGO Y PLANES ATENUANTES) - SUSTITUCIÓN]]&"Controles de Ingenieria; "&año24[[#This Row],[CONTROLES (TRATAMIENTO DEL RIESGO Y PLANES ATENUANTES) - CONTROLES DE INGENIERIA]]&" Controles administrativos; "&año24[[#This Row],[CONTROLES (TRATAMIENTO DEL RIESGO Y PLANES ATENUANTES) - CONTROLES ADMINISTRATIVOS / SEÑALIZACIÓN]]&"Controles de EPP; "&año24[[#This Row],[CONTROLES (TRATAMIENTO DEL RIESGO Y PLANES ATENUANTES) - ELEMENTOS DE PROTECCIÓN PERSONAL]] -> Eliminación del riesgo:NingunaSustitución del riesgo; NingunaControles de Ingenieria; Controles administrativos; Programa de capacitacion y entrenamiento Verificacion esquema de vacunacion Instructivo practica seguro en campo exposición a riesgo biológico COL-HSE-IN-018Controles de EPP; Ver matriz de EPP | AH18: HS Parex Contratista | AI18: 2 Moderado | AJ18: Personas | AK18: 2 Improbable | AL18: =INDEX($AS$3:$AV$6,MATCH($AI18,$AR$3:$AR$6,FALSE),MATCH($AK18,$AS$7:$AV$7,FALSE)) -> 4 | AM18: =IF(año24[[#This Row],[VALORACION DEL RIESGO RESULTANTE CON CONTROLES (Riesgo residual) - Nivel de riesgo]]<=3,"Bajo",IF(año24[[#This Row],[VALORACION DEL RIESGO RESULTANTE CON CONTROLES (Riesgo residual) - Nivel de riesgo]]<=6,"Medio",IF(año24[[#This Row],[VALORACION DEL RIESGO RESULTANTE CON CONTROLES (Riesgo residual) - Nivel de riesgo]]<=12,"Alto","Extremo"))) -> Medio | AO18: =IF(AL18<=4,"SI",IF(AL18>=5,"NO")) -> SI | AP18: ="El nivel del riesgo es"&" "&año24[[#This Row],[VALORACION DEL RIESGO RESULTANTE CON CONTROLES (Riesgo residual) - INTERPRETACIÓN DEL RIESGO]]&" siendo las principales consecuencias las siguientes; "&año24[[#This Row],[Consecuencias (AT/EL)]] -> El nivel del riesgo es Medio siendo las principales consecuencias las siguientes; EL | AQ18: =_xlfn.XLOOKUP(año24[[#This Row],[VALORACION DEL RIESGO RESULTANTE CON CONTROLES (Riesgo residual) - INTERPRETACIÓN DEL RIESGO]], Nivel[Calsificación], Nivel[Imagen]) -> #VALUE!
B19: 10 | C19: 2024 | D19: Campos Parex | E19: MOVILIZACIÓN Y DESMOVILIZACIÓN | F19: Inspección de vía y nueva locación: Recorridos a pie / Supervisión en campo/ inspecciones/ Interaccion con la comunidad / Desplazamiento en vehículos | G19: Ruta de Movilización y Nueva locación | H19: Ignición incontrolada de agentes químicos inflamables por condiciones presentes en el lugar de trabajo | I19: Condiciones_de_seguridad | J19: =_xlfn.XLOOKUP(año24[[#This Row],[PELIGRO -Tipo]], Tabla12[Calsificación], Tabla12[Imagen]) -> #VALUE! | K19: 6.4 Tecnológico | L19: AT | M19: Rutinaria | N19: Interna | O19: 2 | P19: 4 | Q19: 2 | R19: 8 | S19: Contratistas | T19: Programa de mantenimiento de equipos y herramientas | U19: Disponibilidad de extintores Monitoreo de gases Inspección preoperacional de equipos y herramientas | V19: Uso de EPP Capacitación en Manejo de extintores y control de incendios Capacitación brigadistas | W19: 4 Crítico | X19: Personas | Y19: 2 Improbable | Z19: =INDEX($AS$3:$AV$6,MATCH($W19,$AR$3:$AR$6,FALSE),MATCH($Y19,AS$7:$AV$7,FALSE)) -> 8 | AA19: Si (Ver matriz de requisitos legales) | AB19: Ninguna | AC19: Ninguna | AD19: Ninguna | AE19: * Procedimiento de manejo seguro de sustancias químicas * Programa de Gestión Seguridad Basada en el Comportamiento * Procedimiento Sistema Permisos de Trabajo * Anexo HSEQ para contratistas * Plan de emergencias * Uso de herramienta antichispas en áreas calisificadas clase 1 división 1 y 2 | AF19: Ver matriz de EPP | AG19: ="Eliminación del riesgo:"&año24[[#This Row],[CONTROLES (TRATAMIENTO DEL RIESGO Y PLANES ATENUANTES) - ELIMINACIÓN]]&"Sustitución del riesgo; "&año24[[#This Row],[CONTROLES (TRATAMIENTO DEL RIESGO Y PLANES ATENUANTES) - SUSTITUCIÓN]]&"Controles de Ingenieria; "&año24[[#This Row],[CONTROLES (TRATAMIENTO DEL RIESGO Y PLANES ATENUANTES) - CONTROLES DE INGENIERIA]]&" Controles administrativos; "&año24[[#This Row],[CONTROLES (TRATAMIENTO DEL RIESGO Y PLANES ATENUANTES) - CONTROLES ADMINISTRATIVOS / SEÑALIZACIÓN]]&"Controles de EPP; "&año24[[#This Row],[CONTROLES (TRATAMIENTO DEL RIESGO Y PLANES ATENUANTES) - ELEMENTOS DE PROTECCIÓN PERSONAL]] -> Eliminación del riesgo:NingunaSustitución del riesgo; NingunaControles de Ingenieria; Ninguna Controles administrativos; * Procedimiento de manejo seguro de sustancias químicas * Programa de Gestión Seguridad Basada en el Comportamiento * Procedimiento Sistema Permisos de Trabajo * Anexo HSEQ para contratistas * Plan de emergencias * Uso de herramienta antichispas en áreas calisificadas clase 1 división 1 y 2Controles de EPP; Ver matriz de EPP | AH19: HS Parex Contratista | AI19: 4 Crítico | AJ19: Personas | AK19: 1 Remoto | AL19: =INDEX($AS$3:$AV$6,MATCH($AI19,$AR$3:$AR$6,FALSE),MATCH($AK19,$AS$7:$AV$7,FALSE)) -> 4 | AM19: =IF(año24[[#This Row],[VALORACION DEL RIESGO RESULTANTE CON CONTROLES (Riesgo residual) - Nivel de riesgo]]<=3,"Bajo",IF(año24[[#This Row],[VALORACION DEL RIESGO RESULTANTE CON CONTROLES (Riesgo residual) - Nivel de riesgo]]<=6,"Medio",IF(año24[[#This Row],[VALORACION DEL RIESGO RESULTANTE CON CONTROLES (Riesgo residual) - Nivel de riesgo]]<=12,"Alto","Extremo"))) -> Medio | AO19: =IF(AL19<=4,"SI",IF(AL19>=5,"NO")) -> SI | AP19: ="El nivel del riesgo es"&" "&año24[[#This Row],[VALORACION DEL RIESGO RESULTANTE CON CONTROLES (Riesgo residual) - INTERPRETACIÓN DEL RIESGO]]&" siendo las principales consecuencias las siguientes; "&año24[[#This Row],[Consecuencias (AT/EL)]] -> El nivel del riesgo es Medio siendo las principales consecuencias las siguientes; AT | AQ19: =_xlfn.XLOOKUP(año24[[#This Row],[VALORACION DEL RIESGO RESULTANTE CON CONTROLES (Riesgo residual) - INTERPRETACIÓN DEL RIESGO]], Nivel[Calsificación], Nivel[Imagen]) -> #VALUE!
